# ==========================================================
# BAAS VAN HET DORP - bouwt een MEGA dorp rondom de speler
# Gegenereerd door scripts/generate_dorpsbaas.py - niet handmatig aanpassen
# ==========================================================
# Ruimte vrijmaken
fill ~-96 ~0 ~-96 ~-69 ~24 ~-69 air
fill ~-96 ~0 ~-68 ~-69 ~24 ~-41 air
fill ~-96 ~0 ~-40 ~-69 ~24 ~-13 air
fill ~-96 ~0 ~-12 ~-69 ~24 ~15 air
fill ~-96 ~0 ~16 ~-69 ~24 ~43 air
fill ~-96 ~0 ~44 ~-69 ~24 ~71 air
fill ~-96 ~0 ~72 ~-69 ~24 ~96 air
fill ~-68 ~0 ~-96 ~-41 ~24 ~-69 air
fill ~-68 ~0 ~-68 ~-41 ~24 ~-41 air
fill ~-68 ~0 ~-40 ~-41 ~24 ~-13 air
fill ~-68 ~0 ~-12 ~-41 ~24 ~15 air
fill ~-68 ~0 ~16 ~-41 ~24 ~43 air
fill ~-68 ~0 ~44 ~-41 ~24 ~71 air
fill ~-68 ~0 ~72 ~-41 ~24 ~96 air
fill ~-40 ~0 ~-96 ~-13 ~24 ~-69 air
fill ~-40 ~0 ~-68 ~-13 ~24 ~-41 air
fill ~-40 ~0 ~-40 ~-13 ~24 ~-13 air
fill ~-40 ~0 ~-12 ~-13 ~24 ~15 air
fill ~-40 ~0 ~16 ~-13 ~24 ~43 air
fill ~-40 ~0 ~44 ~-13 ~24 ~71 air
fill ~-40 ~0 ~72 ~-13 ~24 ~96 air
fill ~-12 ~0 ~-96 ~15 ~24 ~-69 air
fill ~-12 ~0 ~-68 ~15 ~24 ~-41 air
fill ~-12 ~0 ~-40 ~15 ~24 ~-13 air
fill ~-12 ~0 ~-12 ~15 ~24 ~15 air
fill ~-12 ~0 ~16 ~15 ~24 ~43 air
fill ~-12 ~0 ~44 ~15 ~24 ~71 air
fill ~-12 ~0 ~72 ~15 ~24 ~96 air
fill ~16 ~0 ~-96 ~43 ~24 ~-69 air
fill ~16 ~0 ~-68 ~43 ~24 ~-41 air
fill ~16 ~0 ~-40 ~43 ~24 ~-13 air
fill ~16 ~0 ~-12 ~43 ~24 ~15 air
fill ~16 ~0 ~16 ~43 ~24 ~43 air
fill ~16 ~0 ~44 ~43 ~24 ~71 air
fill ~16 ~0 ~72 ~43 ~24 ~96 air
fill ~44 ~0 ~-96 ~71 ~24 ~-69 air
fill ~44 ~0 ~-68 ~71 ~24 ~-41 air
fill ~44 ~0 ~-40 ~71 ~24 ~-13 air
fill ~44 ~0 ~-12 ~71 ~24 ~15 air
fill ~44 ~0 ~16 ~71 ~24 ~43 air
fill ~44 ~0 ~44 ~71 ~24 ~71 air
fill ~44 ~0 ~72 ~71 ~24 ~96 air
fill ~72 ~0 ~-96 ~96 ~24 ~-69 air
fill ~72 ~0 ~-68 ~96 ~24 ~-41 air
fill ~72 ~0 ~-40 ~96 ~24 ~-13 air
fill ~72 ~0 ~-12 ~96 ~24 ~15 air
fill ~72 ~0 ~16 ~96 ~24 ~43 air
fill ~72 ~0 ~44 ~96 ~24 ~71 air
fill ~72 ~0 ~72 ~96 ~24 ~96 air
# Grasvloer
fill ~-96 ~-1 ~-96 ~-69 ~-1 ~-69 grass_block
fill ~-96 ~-1 ~-68 ~-69 ~-1 ~-41 grass_block
fill ~-96 ~-1 ~-40 ~-69 ~-1 ~-13 grass_block
fill ~-96 ~-1 ~-12 ~-69 ~-1 ~15 grass_block
fill ~-96 ~-1 ~16 ~-69 ~-1 ~43 grass_block
fill ~-96 ~-1 ~44 ~-69 ~-1 ~71 grass_block
fill ~-96 ~-1 ~72 ~-69 ~-1 ~96 grass_block
fill ~-68 ~-1 ~-96 ~-41 ~-1 ~-69 grass_block
fill ~-68 ~-1 ~-68 ~-41 ~-1 ~-41 grass_block
fill ~-68 ~-1 ~-40 ~-41 ~-1 ~-13 grass_block
fill ~-68 ~-1 ~-12 ~-41 ~-1 ~15 grass_block
fill ~-68 ~-1 ~16 ~-41 ~-1 ~43 grass_block
fill ~-68 ~-1 ~44 ~-41 ~-1 ~71 grass_block
fill ~-68 ~-1 ~72 ~-41 ~-1 ~96 grass_block
fill ~-40 ~-1 ~-96 ~-13 ~-1 ~-69 grass_block
fill ~-40 ~-1 ~-68 ~-13 ~-1 ~-41 grass_block
fill ~-40 ~-1 ~-40 ~-13 ~-1 ~-13 grass_block
fill ~-40 ~-1 ~-12 ~-13 ~-1 ~15 grass_block
fill ~-40 ~-1 ~16 ~-13 ~-1 ~43 grass_block
fill ~-40 ~-1 ~44 ~-13 ~-1 ~71 grass_block
fill ~-40 ~-1 ~72 ~-13 ~-1 ~96 grass_block
fill ~-12 ~-1 ~-96 ~15 ~-1 ~-69 grass_block
fill ~-12 ~-1 ~-68 ~15 ~-1 ~-41 grass_block
fill ~-12 ~-1 ~-40 ~15 ~-1 ~-13 grass_block
fill ~-12 ~-1 ~-12 ~15 ~-1 ~15 grass_block
fill ~-12 ~-1 ~16 ~15 ~-1 ~43 grass_block
fill ~-12 ~-1 ~44 ~15 ~-1 ~71 grass_block
fill ~-12 ~-1 ~72 ~15 ~-1 ~96 grass_block
fill ~16 ~-1 ~-96 ~43 ~-1 ~-69 grass_block
fill ~16 ~-1 ~-68 ~43 ~-1 ~-41 grass_block
fill ~16 ~-1 ~-40 ~43 ~-1 ~-13 grass_block
fill ~16 ~-1 ~-12 ~43 ~-1 ~15 grass_block
fill ~16 ~-1 ~16 ~43 ~-1 ~43 grass_block
fill ~16 ~-1 ~44 ~43 ~-1 ~71 grass_block
fill ~16 ~-1 ~72 ~43 ~-1 ~96 grass_block
fill ~44 ~-1 ~-96 ~71 ~-1 ~-69 grass_block
fill ~44 ~-1 ~-68 ~71 ~-1 ~-41 grass_block
fill ~44 ~-1 ~-40 ~71 ~-1 ~-13 grass_block
fill ~44 ~-1 ~-12 ~71 ~-1 ~15 grass_block
fill ~44 ~-1 ~16 ~71 ~-1 ~43 grass_block
fill ~44 ~-1 ~44 ~71 ~-1 ~71 grass_block
fill ~44 ~-1 ~72 ~71 ~-1 ~96 grass_block
fill ~72 ~-1 ~-96 ~96 ~-1 ~-69 grass_block
fill ~72 ~-1 ~-68 ~96 ~-1 ~-41 grass_block
fill ~72 ~-1 ~-40 ~96 ~-1 ~-13 grass_block
fill ~72 ~-1 ~-12 ~96 ~-1 ~15 grass_block
fill ~72 ~-1 ~16 ~96 ~-1 ~43 grass_block
fill ~72 ~-1 ~44 ~96 ~-1 ~71 grass_block
fill ~72 ~-1 ~72 ~96 ~-1 ~96 grass_block
fill ~-96 ~-2 ~-96 ~-69 ~-2 ~-69 dirt
fill ~-96 ~-2 ~-68 ~-69 ~-2 ~-41 dirt
fill ~-96 ~-2 ~-40 ~-69 ~-2 ~-13 dirt
fill ~-96 ~-2 ~-12 ~-69 ~-2 ~15 dirt
fill ~-96 ~-2 ~16 ~-69 ~-2 ~43 dirt
fill ~-96 ~-2 ~44 ~-69 ~-2 ~71 dirt
fill ~-96 ~-2 ~72 ~-69 ~-2 ~96 dirt
fill ~-68 ~-2 ~-96 ~-41 ~-2 ~-69 dirt
fill ~-68 ~-2 ~-68 ~-41 ~-2 ~-41 dirt
fill ~-68 ~-2 ~-40 ~-41 ~-2 ~-13 dirt
fill ~-68 ~-2 ~-12 ~-41 ~-2 ~15 dirt
fill ~-68 ~-2 ~16 ~-41 ~-2 ~43 dirt
fill ~-68 ~-2 ~44 ~-41 ~-2 ~71 dirt
fill ~-68 ~-2 ~72 ~-41 ~-2 ~96 dirt
fill ~-40 ~-2 ~-96 ~-13 ~-2 ~-69 dirt
fill ~-40 ~-2 ~-68 ~-13 ~-2 ~-41 dirt
fill ~-40 ~-2 ~-40 ~-13 ~-2 ~-13 dirt
fill ~-40 ~-2 ~-12 ~-13 ~-2 ~15 dirt
fill ~-40 ~-2 ~16 ~-13 ~-2 ~43 dirt
fill ~-40 ~-2 ~44 ~-13 ~-2 ~71 dirt
fill ~-40 ~-2 ~72 ~-13 ~-2 ~96 dirt
fill ~-12 ~-2 ~-96 ~15 ~-2 ~-69 dirt
fill ~-12 ~-2 ~-68 ~15 ~-2 ~-41 dirt
fill ~-12 ~-2 ~-40 ~15 ~-2 ~-13 dirt
fill ~-12 ~-2 ~-12 ~15 ~-2 ~15 dirt
fill ~-12 ~-2 ~16 ~15 ~-2 ~43 dirt
fill ~-12 ~-2 ~44 ~15 ~-2 ~71 dirt
fill ~-12 ~-2 ~72 ~15 ~-2 ~96 dirt
fill ~16 ~-2 ~-96 ~43 ~-2 ~-69 dirt
fill ~16 ~-2 ~-68 ~43 ~-2 ~-41 dirt
fill ~16 ~-2 ~-40 ~43 ~-2 ~-13 dirt
fill ~16 ~-2 ~-12 ~43 ~-2 ~15 dirt
fill ~16 ~-2 ~16 ~43 ~-2 ~43 dirt
fill ~16 ~-2 ~44 ~43 ~-2 ~71 dirt
fill ~16 ~-2 ~72 ~43 ~-2 ~96 dirt
fill ~44 ~-2 ~-96 ~71 ~-2 ~-69 dirt
fill ~44 ~-2 ~-68 ~71 ~-2 ~-41 dirt
fill ~44 ~-2 ~-40 ~71 ~-2 ~-13 dirt
fill ~44 ~-2 ~-12 ~71 ~-2 ~15 dirt
fill ~44 ~-2 ~16 ~71 ~-2 ~43 dirt
fill ~44 ~-2 ~44 ~71 ~-2 ~71 dirt
fill ~44 ~-2 ~72 ~71 ~-2 ~96 dirt
fill ~72 ~-2 ~-96 ~96 ~-2 ~-69 dirt
fill ~72 ~-2 ~-68 ~96 ~-2 ~-41 dirt
fill ~72 ~-2 ~-40 ~96 ~-2 ~-13 dirt
fill ~72 ~-2 ~-12 ~96 ~-2 ~15 dirt
fill ~72 ~-2 ~16 ~96 ~-2 ~43 dirt
fill ~72 ~-2 ~44 ~96 ~-2 ~71 dirt
fill ~72 ~-2 ~72 ~96 ~-2 ~96 dirt
# Wegen (raster)
fill ~-87 ~-1 ~-96 ~-85 ~-1 ~-69 stone
fill ~-87 ~-1 ~-68 ~-85 ~-1 ~-41 stone
fill ~-87 ~-1 ~-40 ~-85 ~-1 ~-13 stone
fill ~-87 ~-1 ~-12 ~-85 ~-1 ~15 stone
fill ~-87 ~-1 ~16 ~-85 ~-1 ~43 stone
fill ~-87 ~-1 ~44 ~-85 ~-1 ~71 stone
fill ~-87 ~-1 ~72 ~-85 ~-1 ~96 stone
fill ~-67 ~-1 ~-96 ~-65 ~-1 ~-69 stone
fill ~-67 ~-1 ~-68 ~-65 ~-1 ~-41 stone
fill ~-67 ~-1 ~-40 ~-65 ~-1 ~-13 stone
fill ~-67 ~-1 ~-12 ~-65 ~-1 ~15 stone
fill ~-67 ~-1 ~16 ~-65 ~-1 ~43 stone
fill ~-67 ~-1 ~44 ~-65 ~-1 ~71 stone
fill ~-67 ~-1 ~72 ~-65 ~-1 ~96 stone
fill ~-47 ~-1 ~-96 ~-45 ~-1 ~-69 stone
fill ~-47 ~-1 ~-68 ~-45 ~-1 ~-41 stone
fill ~-47 ~-1 ~-40 ~-45 ~-1 ~-13 stone
fill ~-47 ~-1 ~-12 ~-45 ~-1 ~15 stone
fill ~-47 ~-1 ~16 ~-45 ~-1 ~43 stone
fill ~-47 ~-1 ~44 ~-45 ~-1 ~71 stone
fill ~-47 ~-1 ~72 ~-45 ~-1 ~96 stone
fill ~-27 ~-1 ~-96 ~-25 ~-1 ~-69 stone
fill ~-27 ~-1 ~-68 ~-25 ~-1 ~-41 stone
fill ~-27 ~-1 ~-40 ~-25 ~-1 ~-13 stone
fill ~-27 ~-1 ~-12 ~-25 ~-1 ~15 stone
fill ~-27 ~-1 ~16 ~-25 ~-1 ~43 stone
fill ~-27 ~-1 ~44 ~-25 ~-1 ~71 stone
fill ~-27 ~-1 ~72 ~-25 ~-1 ~96 stone
fill ~-7 ~-1 ~-96 ~-5 ~-1 ~-69 stone
fill ~-7 ~-1 ~-68 ~-5 ~-1 ~-41 stone
fill ~-7 ~-1 ~-40 ~-5 ~-1 ~-13 stone
fill ~-7 ~-1 ~-12 ~-5 ~-1 ~15 stone
fill ~-7 ~-1 ~16 ~-5 ~-1 ~43 stone
fill ~-7 ~-1 ~44 ~-5 ~-1 ~71 stone
fill ~-7 ~-1 ~72 ~-5 ~-1 ~96 stone
fill ~13 ~-1 ~-96 ~15 ~-1 ~-69 stone
fill ~13 ~-1 ~-68 ~15 ~-1 ~-41 stone
fill ~13 ~-1 ~-40 ~15 ~-1 ~-13 stone
fill ~13 ~-1 ~-12 ~15 ~-1 ~15 stone
fill ~13 ~-1 ~16 ~15 ~-1 ~43 stone
fill ~13 ~-1 ~44 ~15 ~-1 ~71 stone
fill ~13 ~-1 ~72 ~15 ~-1 ~96 stone
fill ~33 ~-1 ~-96 ~35 ~-1 ~-69 stone
fill ~33 ~-1 ~-68 ~35 ~-1 ~-41 stone
fill ~33 ~-1 ~-40 ~35 ~-1 ~-13 stone
fill ~33 ~-1 ~-12 ~35 ~-1 ~15 stone
fill ~33 ~-1 ~16 ~35 ~-1 ~43 stone
fill ~33 ~-1 ~44 ~35 ~-1 ~71 stone
fill ~33 ~-1 ~72 ~35 ~-1 ~96 stone
fill ~53 ~-1 ~-96 ~55 ~-1 ~-69 stone
fill ~53 ~-1 ~-68 ~55 ~-1 ~-41 stone
fill ~53 ~-1 ~-40 ~55 ~-1 ~-13 stone
fill ~53 ~-1 ~-12 ~55 ~-1 ~15 stone
fill ~53 ~-1 ~16 ~55 ~-1 ~43 stone
fill ~53 ~-1 ~44 ~55 ~-1 ~71 stone
fill ~53 ~-1 ~72 ~55 ~-1 ~96 stone
fill ~73 ~-1 ~-96 ~75 ~-1 ~-69 stone
fill ~73 ~-1 ~-68 ~75 ~-1 ~-41 stone
fill ~73 ~-1 ~-40 ~75 ~-1 ~-13 stone
fill ~73 ~-1 ~-12 ~75 ~-1 ~15 stone
fill ~73 ~-1 ~16 ~75 ~-1 ~43 stone
fill ~73 ~-1 ~44 ~75 ~-1 ~71 stone
fill ~73 ~-1 ~72 ~75 ~-1 ~96 stone
fill ~-96 ~-1 ~-87 ~-69 ~-1 ~-85 stone
fill ~-68 ~-1 ~-87 ~-41 ~-1 ~-85 stone
fill ~-40 ~-1 ~-87 ~-13 ~-1 ~-85 stone
fill ~-12 ~-1 ~-87 ~15 ~-1 ~-85 stone
fill ~16 ~-1 ~-87 ~43 ~-1 ~-85 stone
fill ~44 ~-1 ~-87 ~71 ~-1 ~-85 stone
fill ~72 ~-1 ~-87 ~96 ~-1 ~-85 stone
fill ~-96 ~-1 ~-67 ~-69 ~-1 ~-65 stone
fill ~-68 ~-1 ~-67 ~-41 ~-1 ~-65 stone
fill ~-40 ~-1 ~-67 ~-13 ~-1 ~-65 stone
fill ~-12 ~-1 ~-67 ~15 ~-1 ~-65 stone
fill ~16 ~-1 ~-67 ~43 ~-1 ~-65 stone
fill ~44 ~-1 ~-67 ~71 ~-1 ~-65 stone
fill ~72 ~-1 ~-67 ~96 ~-1 ~-65 stone
fill ~-96 ~-1 ~-47 ~-69 ~-1 ~-45 stone
fill ~-68 ~-1 ~-47 ~-41 ~-1 ~-45 stone
fill ~-40 ~-1 ~-47 ~-13 ~-1 ~-45 stone
fill ~-12 ~-1 ~-47 ~15 ~-1 ~-45 stone
fill ~16 ~-1 ~-47 ~43 ~-1 ~-45 stone
fill ~44 ~-1 ~-47 ~71 ~-1 ~-45 stone
fill ~72 ~-1 ~-47 ~96 ~-1 ~-45 stone
fill ~-96 ~-1 ~-27 ~-69 ~-1 ~-25 stone
fill ~-68 ~-1 ~-27 ~-41 ~-1 ~-25 stone
fill ~-40 ~-1 ~-27 ~-13 ~-1 ~-25 stone
fill ~-12 ~-1 ~-27 ~15 ~-1 ~-25 stone
fill ~16 ~-1 ~-27 ~43 ~-1 ~-25 stone
fill ~44 ~-1 ~-27 ~71 ~-1 ~-25 stone
fill ~72 ~-1 ~-27 ~96 ~-1 ~-25 stone
fill ~-96 ~-1 ~-7 ~-69 ~-1 ~-5 stone
fill ~-68 ~-1 ~-7 ~-41 ~-1 ~-5 stone
fill ~-40 ~-1 ~-7 ~-13 ~-1 ~-5 stone
fill ~-12 ~-1 ~-7 ~15 ~-1 ~-5 stone
fill ~16 ~-1 ~-7 ~43 ~-1 ~-5 stone
fill ~44 ~-1 ~-7 ~71 ~-1 ~-5 stone
fill ~72 ~-1 ~-7 ~96 ~-1 ~-5 stone
fill ~-96 ~-1 ~13 ~-69 ~-1 ~15 stone
fill ~-68 ~-1 ~13 ~-41 ~-1 ~15 stone
fill ~-40 ~-1 ~13 ~-13 ~-1 ~15 stone
fill ~-12 ~-1 ~13 ~15 ~-1 ~15 stone
fill ~16 ~-1 ~13 ~43 ~-1 ~15 stone
fill ~44 ~-1 ~13 ~71 ~-1 ~15 stone
fill ~72 ~-1 ~13 ~96 ~-1 ~15 stone
fill ~-96 ~-1 ~33 ~-69 ~-1 ~35 stone
fill ~-68 ~-1 ~33 ~-41 ~-1 ~35 stone
fill ~-40 ~-1 ~33 ~-13 ~-1 ~35 stone
fill ~-12 ~-1 ~33 ~15 ~-1 ~35 stone
fill ~16 ~-1 ~33 ~43 ~-1 ~35 stone
fill ~44 ~-1 ~33 ~71 ~-1 ~35 stone
fill ~72 ~-1 ~33 ~96 ~-1 ~35 stone
fill ~-96 ~-1 ~53 ~-69 ~-1 ~55 stone
fill ~-68 ~-1 ~53 ~-41 ~-1 ~55 stone
fill ~-40 ~-1 ~53 ~-13 ~-1 ~55 stone
fill ~-12 ~-1 ~53 ~15 ~-1 ~55 stone
fill ~16 ~-1 ~53 ~43 ~-1 ~55 stone
fill ~44 ~-1 ~53 ~71 ~-1 ~55 stone
fill ~72 ~-1 ~53 ~96 ~-1 ~55 stone
fill ~-96 ~-1 ~73 ~-69 ~-1 ~75 stone
fill ~-68 ~-1 ~73 ~-41 ~-1 ~75 stone
fill ~-40 ~-1 ~73 ~-13 ~-1 ~75 stone
fill ~-12 ~-1 ~73 ~15 ~-1 ~75 stone
fill ~16 ~-1 ~73 ~43 ~-1 ~75 stone
fill ~44 ~-1 ~73 ~71 ~-1 ~75 stone
fill ~72 ~-1 ~73 ~96 ~-1 ~75 stone
setblock ~-84 ~0 ~-84 oak_fence
setblock ~-84 ~1 ~-84 oak_fence
setblock ~-84 ~2 ~-84 lit_pumpkin
setblock ~-84 ~0 ~-64 oak_fence
setblock ~-84 ~1 ~-64 oak_fence
setblock ~-84 ~2 ~-64 lit_pumpkin
setblock ~-84 ~0 ~-44 oak_fence
setblock ~-84 ~1 ~-44 oak_fence
setblock ~-84 ~2 ~-44 lit_pumpkin
setblock ~-84 ~0 ~-24 oak_fence
setblock ~-84 ~1 ~-24 oak_fence
setblock ~-84 ~2 ~-24 lit_pumpkin
setblock ~-84 ~0 ~-4 oak_fence
setblock ~-84 ~1 ~-4 oak_fence
setblock ~-84 ~2 ~-4 lit_pumpkin
setblock ~-84 ~0 ~16 oak_fence
setblock ~-84 ~1 ~16 oak_fence
setblock ~-84 ~2 ~16 lit_pumpkin
setblock ~-84 ~0 ~36 oak_fence
setblock ~-84 ~1 ~36 oak_fence
setblock ~-84 ~2 ~36 lit_pumpkin
setblock ~-84 ~0 ~56 oak_fence
setblock ~-84 ~1 ~56 oak_fence
setblock ~-84 ~2 ~56 lit_pumpkin
setblock ~-84 ~0 ~76 oak_fence
setblock ~-84 ~1 ~76 oak_fence
setblock ~-84 ~2 ~76 lit_pumpkin
setblock ~-64 ~0 ~-84 oak_fence
setblock ~-64 ~1 ~-84 oak_fence
setblock ~-64 ~2 ~-84 lit_pumpkin
setblock ~-64 ~0 ~-64 oak_fence
setblock ~-64 ~1 ~-64 oak_fence
setblock ~-64 ~2 ~-64 lit_pumpkin
setblock ~-64 ~0 ~-44 oak_fence
setblock ~-64 ~1 ~-44 oak_fence
setblock ~-64 ~2 ~-44 lit_pumpkin
setblock ~-64 ~0 ~-24 oak_fence
setblock ~-64 ~1 ~-24 oak_fence
setblock ~-64 ~2 ~-24 lit_pumpkin
setblock ~-64 ~0 ~-4 oak_fence
setblock ~-64 ~1 ~-4 oak_fence
setblock ~-64 ~2 ~-4 lit_pumpkin
setblock ~-64 ~0 ~16 oak_fence
setblock ~-64 ~1 ~16 oak_fence
setblock ~-64 ~2 ~16 lit_pumpkin
setblock ~-64 ~0 ~36 oak_fence
setblock ~-64 ~1 ~36 oak_fence
setblock ~-64 ~2 ~36 lit_pumpkin
setblock ~-64 ~0 ~56 oak_fence
setblock ~-64 ~1 ~56 oak_fence
setblock ~-64 ~2 ~56 lit_pumpkin
setblock ~-64 ~0 ~76 oak_fence
setblock ~-64 ~1 ~76 oak_fence
setblock ~-64 ~2 ~76 lit_pumpkin
setblock ~-44 ~0 ~-84 oak_fence
setblock ~-44 ~1 ~-84 oak_fence
setblock ~-44 ~2 ~-84 lit_pumpkin
setblock ~-44 ~0 ~-64 oak_fence
setblock ~-44 ~1 ~-64 oak_fence
setblock ~-44 ~2 ~-64 lit_pumpkin
setblock ~-44 ~0 ~-44 oak_fence
setblock ~-44 ~1 ~-44 oak_fence
setblock ~-44 ~2 ~-44 lit_pumpkin
setblock ~-44 ~0 ~-24 oak_fence
setblock ~-44 ~1 ~-24 oak_fence
setblock ~-44 ~2 ~-24 lit_pumpkin
setblock ~-44 ~0 ~-4 oak_fence
setblock ~-44 ~1 ~-4 oak_fence
setblock ~-44 ~2 ~-4 lit_pumpkin
setblock ~-44 ~0 ~16 oak_fence
setblock ~-44 ~1 ~16 oak_fence
setblock ~-44 ~2 ~16 lit_pumpkin
setblock ~-44 ~0 ~36 oak_fence
setblock ~-44 ~1 ~36 oak_fence
setblock ~-44 ~2 ~36 lit_pumpkin
setblock ~-44 ~0 ~56 oak_fence
setblock ~-44 ~1 ~56 oak_fence
setblock ~-44 ~2 ~56 lit_pumpkin
setblock ~-44 ~0 ~76 oak_fence
setblock ~-44 ~1 ~76 oak_fence
setblock ~-44 ~2 ~76 lit_pumpkin
setblock ~-24 ~0 ~-84 oak_fence
setblock ~-24 ~1 ~-84 oak_fence
setblock ~-24 ~2 ~-84 lit_pumpkin
setblock ~-24 ~0 ~-64 oak_fence
setblock ~-24 ~1 ~-64 oak_fence
setblock ~-24 ~2 ~-64 lit_pumpkin
setblock ~-24 ~0 ~-44 oak_fence
setblock ~-24 ~1 ~-44 oak_fence
setblock ~-24 ~2 ~-44 lit_pumpkin
setblock ~-24 ~0 ~-24 oak_fence
setblock ~-24 ~1 ~-24 oak_fence
setblock ~-24 ~2 ~-24 lit_pumpkin
setblock ~-24 ~0 ~-4 oak_fence
setblock ~-24 ~1 ~-4 oak_fence
setblock ~-24 ~2 ~-4 lit_pumpkin
setblock ~-24 ~0 ~16 oak_fence
setblock ~-24 ~1 ~16 oak_fence
setblock ~-24 ~2 ~16 lit_pumpkin
setblock ~-24 ~0 ~36 oak_fence
setblock ~-24 ~1 ~36 oak_fence
setblock ~-24 ~2 ~36 lit_pumpkin
setblock ~-24 ~0 ~56 oak_fence
setblock ~-24 ~1 ~56 oak_fence
setblock ~-24 ~2 ~56 lit_pumpkin
setblock ~-24 ~0 ~76 oak_fence
setblock ~-24 ~1 ~76 oak_fence
setblock ~-24 ~2 ~76 lit_pumpkin
setblock ~-4 ~0 ~-84 oak_fence
setblock ~-4 ~1 ~-84 oak_fence
setblock ~-4 ~2 ~-84 lit_pumpkin
setblock ~-4 ~0 ~-64 oak_fence
setblock ~-4 ~1 ~-64 oak_fence
setblock ~-4 ~2 ~-64 lit_pumpkin
setblock ~-4 ~0 ~-44 oak_fence
setblock ~-4 ~1 ~-44 oak_fence
setblock ~-4 ~2 ~-44 lit_pumpkin
setblock ~-4 ~0 ~-24 oak_fence
setblock ~-4 ~1 ~-24 oak_fence
setblock ~-4 ~2 ~-24 lit_pumpkin
setblock ~-4 ~0 ~36 oak_fence
setblock ~-4 ~1 ~36 oak_fence
setblock ~-4 ~2 ~36 lit_pumpkin
setblock ~-4 ~0 ~56 oak_fence
setblock ~-4 ~1 ~56 oak_fence
setblock ~-4 ~2 ~56 lit_pumpkin
setblock ~-4 ~0 ~76 oak_fence
setblock ~-4 ~1 ~76 oak_fence
setblock ~-4 ~2 ~76 lit_pumpkin
setblock ~16 ~0 ~-84 oak_fence
setblock ~16 ~1 ~-84 oak_fence
setblock ~16 ~2 ~-84 lit_pumpkin
setblock ~16 ~0 ~-64 oak_fence
setblock ~16 ~1 ~-64 oak_fence
setblock ~16 ~2 ~-64 lit_pumpkin
setblock ~16 ~0 ~-44 oak_fence
setblock ~16 ~1 ~-44 oak_fence
setblock ~16 ~2 ~-44 lit_pumpkin
setblock ~16 ~0 ~-24 oak_fence
setblock ~16 ~1 ~-24 oak_fence
setblock ~16 ~2 ~-24 lit_pumpkin
setblock ~16 ~0 ~36 oak_fence
setblock ~16 ~1 ~36 oak_fence
setblock ~16 ~2 ~36 lit_pumpkin
setblock ~16 ~0 ~56 oak_fence
setblock ~16 ~1 ~56 oak_fence
setblock ~16 ~2 ~56 lit_pumpkin
setblock ~16 ~0 ~76 oak_fence
setblock ~16 ~1 ~76 oak_fence
setblock ~16 ~2 ~76 lit_pumpkin
setblock ~36 ~0 ~-84 oak_fence
setblock ~36 ~1 ~-84 oak_fence
setblock ~36 ~2 ~-84 lit_pumpkin
setblock ~36 ~0 ~-64 oak_fence
setblock ~36 ~1 ~-64 oak_fence
setblock ~36 ~2 ~-64 lit_pumpkin
setblock ~36 ~0 ~-44 oak_fence
setblock ~36 ~1 ~-44 oak_fence
setblock ~36 ~2 ~-44 lit_pumpkin
setblock ~36 ~0 ~-24 oak_fence
setblock ~36 ~1 ~-24 oak_fence
setblock ~36 ~2 ~-24 lit_pumpkin
setblock ~36 ~0 ~-4 oak_fence
setblock ~36 ~1 ~-4 oak_fence
setblock ~36 ~2 ~-4 lit_pumpkin
setblock ~36 ~0 ~16 oak_fence
setblock ~36 ~1 ~16 oak_fence
setblock ~36 ~2 ~16 lit_pumpkin
setblock ~36 ~0 ~36 oak_fence
setblock ~36 ~1 ~36 oak_fence
setblock ~36 ~2 ~36 lit_pumpkin
setblock ~36 ~0 ~56 oak_fence
setblock ~36 ~1 ~56 oak_fence
setblock ~36 ~2 ~56 lit_pumpkin
setblock ~36 ~0 ~76 oak_fence
setblock ~36 ~1 ~76 oak_fence
setblock ~36 ~2 ~76 lit_pumpkin
setblock ~56 ~0 ~-84 oak_fence
setblock ~56 ~1 ~-84 oak_fence
setblock ~56 ~2 ~-84 lit_pumpkin
setblock ~56 ~0 ~-64 oak_fence
setblock ~56 ~1 ~-64 oak_fence
setblock ~56 ~2 ~-64 lit_pumpkin
setblock ~56 ~0 ~-44 oak_fence
setblock ~56 ~1 ~-44 oak_fence
setblock ~56 ~2 ~-44 lit_pumpkin
setblock ~56 ~0 ~-24 oak_fence
setblock ~56 ~1 ~-24 oak_fence
setblock ~56 ~2 ~-24 lit_pumpkin
setblock ~56 ~0 ~-4 oak_fence
setblock ~56 ~1 ~-4 oak_fence
setblock ~56 ~2 ~-4 lit_pumpkin
setblock ~56 ~0 ~16 oak_fence
setblock ~56 ~1 ~16 oak_fence
setblock ~56 ~2 ~16 lit_pumpkin
setblock ~56 ~0 ~36 oak_fence
setblock ~56 ~1 ~36 oak_fence
setblock ~56 ~2 ~36 lit_pumpkin
setblock ~56 ~0 ~56 oak_fence
setblock ~56 ~1 ~56 oak_fence
setblock ~56 ~2 ~56 lit_pumpkin
setblock ~56 ~0 ~76 oak_fence
setblock ~56 ~1 ~76 oak_fence
setblock ~56 ~2 ~76 lit_pumpkin
setblock ~76 ~0 ~-84 oak_fence
setblock ~76 ~1 ~-84 oak_fence
setblock ~76 ~2 ~-84 lit_pumpkin
setblock ~76 ~0 ~-64 oak_fence
setblock ~76 ~1 ~-64 oak_fence
setblock ~76 ~2 ~-64 lit_pumpkin
setblock ~76 ~0 ~-44 oak_fence
setblock ~76 ~1 ~-44 oak_fence
setblock ~76 ~2 ~-44 lit_pumpkin
setblock ~76 ~0 ~-24 oak_fence
setblock ~76 ~1 ~-24 oak_fence
setblock ~76 ~2 ~-24 lit_pumpkin
setblock ~76 ~0 ~-4 oak_fence
setblock ~76 ~1 ~-4 oak_fence
setblock ~76 ~2 ~-4 lit_pumpkin
setblock ~76 ~0 ~16 oak_fence
setblock ~76 ~1 ~16 oak_fence
setblock ~76 ~2 ~16 lit_pumpkin
setblock ~76 ~0 ~36 oak_fence
setblock ~76 ~1 ~36 oak_fence
setblock ~76 ~2 ~36 lit_pumpkin
setblock ~76 ~0 ~56 oak_fence
setblock ~76 ~1 ~56 oak_fence
setblock ~76 ~2 ~56 lit_pumpkin
setblock ~76 ~0 ~76 oak_fence
setblock ~76 ~1 ~76 oak_fence
setblock ~76 ~2 ~76 lit_pumpkin
# Dorpshuisjes
fill ~-79 ~-1 ~-79 ~-73 ~-1 ~-73 oak_planks
fill ~-79 ~0 ~-79 ~-73 ~3 ~-73 oak_planks hollow
fill ~-79 ~4 ~-79 ~-73 ~4 ~-73 dark_oak_planks
setblock ~-76 ~0 ~-79 air
setblock ~-76 ~1 ~-79 air
setblock ~-73 ~2 ~-76 glass
setblock ~-79 ~2 ~-76 glass
setblock ~-76 ~3 ~-76 torch
fill ~-79 ~-1 ~-59 ~-73 ~-1 ~-53 spruce_planks
fill ~-79 ~0 ~-59 ~-73 ~3 ~-53 spruce_planks hollow
fill ~-79 ~4 ~-59 ~-73 ~4 ~-53 brick_block
setblock ~-76 ~0 ~-59 air
setblock ~-76 ~1 ~-59 air
setblock ~-73 ~2 ~-56 glass
setblock ~-79 ~2 ~-56 glass
setblock ~-76 ~3 ~-56 torch
fill ~-79 ~-1 ~-39 ~-73 ~-1 ~-33 birch_planks
fill ~-79 ~0 ~-39 ~-73 ~3 ~-33 birch_planks hollow
fill ~-79 ~4 ~-39 ~-73 ~4 ~-33 nether_brick
setblock ~-76 ~0 ~-39 air
setblock ~-76 ~1 ~-39 air
setblock ~-73 ~2 ~-36 glass
setblock ~-79 ~2 ~-36 glass
setblock ~-76 ~3 ~-36 torch
fill ~-79 ~-1 ~-19 ~-73 ~-1 ~-13 white_terracotta
fill ~-79 ~0 ~-19 ~-73 ~3 ~-13 white_terracotta hollow
fill ~-79 ~4 ~-19 ~-73 ~4 ~-13 spruce_planks
setblock ~-76 ~0 ~-19 air
setblock ~-76 ~1 ~-19 air
setblock ~-73 ~2 ~-16 glass
setblock ~-79 ~2 ~-16 glass
setblock ~-76 ~3 ~-16 torch
fill ~-79 ~-1 ~1 ~-73 ~-1 ~7 light_gray_terracotta
fill ~-79 ~0 ~1 ~-73 ~3 ~7 light_gray_terracotta hollow
fill ~-79 ~4 ~1 ~-73 ~4 ~7 dark_oak_planks
setblock ~-76 ~0 ~1 air
setblock ~-76 ~1 ~1 air
setblock ~-73 ~2 ~4 glass
setblock ~-79 ~2 ~4 glass
setblock ~-76 ~3 ~4 torch
fill ~-79 ~-1 ~21 ~-73 ~-1 ~27 brown_terracotta
fill ~-79 ~0 ~21 ~-73 ~3 ~27 brown_terracotta hollow
fill ~-79 ~4 ~21 ~-73 ~4 ~27 brick_block
setblock ~-76 ~0 ~21 air
setblock ~-76 ~1 ~21 air
setblock ~-73 ~2 ~24 glass
setblock ~-79 ~2 ~24 glass
setblock ~-76 ~3 ~24 torch
fill ~-79 ~-1 ~41 ~-73 ~-1 ~47 oak_planks
fill ~-79 ~0 ~41 ~-73 ~3 ~47 oak_planks hollow
fill ~-79 ~4 ~41 ~-73 ~4 ~47 nether_brick
setblock ~-76 ~0 ~41 air
setblock ~-76 ~1 ~41 air
setblock ~-73 ~2 ~44 glass
setblock ~-79 ~2 ~44 glass
setblock ~-76 ~3 ~44 torch
fill ~-79 ~-1 ~61 ~-73 ~-1 ~67 spruce_planks
fill ~-79 ~0 ~61 ~-73 ~3 ~67 spruce_planks hollow
fill ~-79 ~4 ~61 ~-73 ~4 ~67 spruce_planks
setblock ~-76 ~0 ~61 air
setblock ~-76 ~1 ~61 air
setblock ~-73 ~2 ~64 glass
setblock ~-79 ~2 ~64 glass
setblock ~-76 ~3 ~64 torch
fill ~-79 ~-1 ~81 ~-73 ~-1 ~87 birch_planks
fill ~-79 ~0 ~81 ~-73 ~3 ~87 birch_planks hollow
fill ~-79 ~4 ~81 ~-73 ~4 ~87 dark_oak_planks
setblock ~-76 ~0 ~81 air
setblock ~-76 ~1 ~81 air
setblock ~-73 ~2 ~84 glass
setblock ~-79 ~2 ~84 glass
setblock ~-76 ~3 ~84 torch
fill ~-59 ~-1 ~-79 ~-53 ~-1 ~-73 white_terracotta
fill ~-59 ~0 ~-79 ~-53 ~3 ~-73 white_terracotta hollow
fill ~-59 ~4 ~-79 ~-53 ~4 ~-73 brick_block
setblock ~-56 ~0 ~-79 air
setblock ~-56 ~1 ~-79 air
setblock ~-53 ~2 ~-76 glass
setblock ~-59 ~2 ~-76 glass
setblock ~-56 ~3 ~-76 torch
fill ~-59 ~-1 ~-59 ~-53 ~-1 ~-53 light_gray_terracotta
fill ~-59 ~0 ~-59 ~-53 ~3 ~-53 light_gray_terracotta hollow
fill ~-59 ~4 ~-59 ~-53 ~4 ~-53 nether_brick
setblock ~-56 ~0 ~-59 air
setblock ~-56 ~1 ~-59 air
setblock ~-53 ~2 ~-56 glass
setblock ~-59 ~2 ~-56 glass
setblock ~-56 ~3 ~-56 torch
fill ~-59 ~-1 ~-39 ~-53 ~-1 ~-33 brown_terracotta
fill ~-59 ~0 ~-39 ~-53 ~3 ~-33 brown_terracotta hollow
fill ~-59 ~4 ~-39 ~-53 ~4 ~-33 spruce_planks
setblock ~-56 ~0 ~-39 air
setblock ~-56 ~1 ~-39 air
setblock ~-53 ~2 ~-36 glass
setblock ~-59 ~2 ~-36 glass
setblock ~-56 ~3 ~-36 torch
fill ~-59 ~-1 ~-19 ~-53 ~-1 ~-13 oak_planks
fill ~-59 ~0 ~-19 ~-53 ~3 ~-13 oak_planks hollow
fill ~-59 ~4 ~-19 ~-53 ~4 ~-13 dark_oak_planks
setblock ~-56 ~0 ~-19 air
setblock ~-56 ~1 ~-19 air
setblock ~-53 ~2 ~-16 glass
setblock ~-59 ~2 ~-16 glass
setblock ~-56 ~3 ~-16 torch
fill ~-59 ~-1 ~1 ~-53 ~-1 ~7 spruce_planks
fill ~-59 ~0 ~1 ~-53 ~3 ~7 spruce_planks hollow
fill ~-59 ~4 ~1 ~-53 ~4 ~7 brick_block
setblock ~-56 ~0 ~1 air
setblock ~-56 ~1 ~1 air
setblock ~-53 ~2 ~4 glass
setblock ~-59 ~2 ~4 glass
setblock ~-56 ~3 ~4 torch
fill ~-59 ~-1 ~21 ~-53 ~-1 ~27 birch_planks
fill ~-59 ~0 ~21 ~-53 ~3 ~27 birch_planks hollow
fill ~-59 ~4 ~21 ~-53 ~4 ~27 nether_brick
setblock ~-56 ~0 ~21 air
setblock ~-56 ~1 ~21 air
setblock ~-53 ~2 ~24 glass
setblock ~-59 ~2 ~24 glass
setblock ~-56 ~3 ~24 torch
fill ~-59 ~-1 ~41 ~-53 ~-1 ~47 white_terracotta
fill ~-59 ~0 ~41 ~-53 ~3 ~47 white_terracotta hollow
fill ~-59 ~4 ~41 ~-53 ~4 ~47 spruce_planks
setblock ~-56 ~0 ~41 air
setblock ~-56 ~1 ~41 air
setblock ~-53 ~2 ~44 glass
setblock ~-59 ~2 ~44 glass
setblock ~-56 ~3 ~44 torch
fill ~-59 ~-1 ~61 ~-53 ~-1 ~67 light_gray_terracotta
fill ~-59 ~0 ~61 ~-53 ~3 ~67 light_gray_terracotta hollow
fill ~-59 ~4 ~61 ~-53 ~4 ~67 dark_oak_planks
setblock ~-56 ~0 ~61 air
setblock ~-56 ~1 ~61 air
setblock ~-53 ~2 ~64 glass
setblock ~-59 ~2 ~64 glass
setblock ~-56 ~3 ~64 torch
fill ~-59 ~-1 ~81 ~-53 ~-1 ~87 brown_terracotta
fill ~-59 ~0 ~81 ~-53 ~3 ~87 brown_terracotta hollow
fill ~-59 ~4 ~81 ~-53 ~4 ~87 brick_block
setblock ~-56 ~0 ~81 air
setblock ~-56 ~1 ~81 air
setblock ~-53 ~2 ~84 glass
setblock ~-59 ~2 ~84 glass
setblock ~-56 ~3 ~84 torch
fill ~-39 ~-1 ~-79 ~-33 ~-1 ~-73 oak_planks
fill ~-39 ~0 ~-79 ~-33 ~3 ~-73 oak_planks hollow
fill ~-39 ~4 ~-79 ~-33 ~4 ~-73 nether_brick
setblock ~-36 ~0 ~-79 air
setblock ~-36 ~1 ~-79 air
setblock ~-33 ~2 ~-76 glass
setblock ~-39 ~2 ~-76 glass
setblock ~-36 ~3 ~-76 torch
fill ~-39 ~-1 ~-59 ~-33 ~-1 ~-53 spruce_planks
fill ~-39 ~0 ~-59 ~-33 ~3 ~-53 spruce_planks hollow
fill ~-39 ~4 ~-59 ~-33 ~4 ~-53 spruce_planks
setblock ~-36 ~0 ~-59 air
setblock ~-36 ~1 ~-59 air
setblock ~-33 ~2 ~-56 glass
setblock ~-39 ~2 ~-56 glass
setblock ~-36 ~3 ~-56 torch
fill ~-39 ~-1 ~-39 ~-33 ~-1 ~-33 birch_planks
fill ~-39 ~0 ~-39 ~-33 ~3 ~-33 birch_planks hollow
fill ~-39 ~4 ~-39 ~-33 ~4 ~-33 dark_oak_planks
setblock ~-36 ~0 ~-39 air
setblock ~-36 ~1 ~-39 air
setblock ~-33 ~2 ~-36 glass
setblock ~-39 ~2 ~-36 glass
setblock ~-36 ~3 ~-36 torch
fill ~-39 ~-1 ~-19 ~-33 ~-1 ~-13 white_terracotta
fill ~-39 ~0 ~-19 ~-33 ~3 ~-13 white_terracotta hollow
fill ~-39 ~4 ~-19 ~-33 ~4 ~-13 brick_block
setblock ~-36 ~0 ~-19 air
setblock ~-36 ~1 ~-19 air
setblock ~-33 ~2 ~-16 glass
setblock ~-39 ~2 ~-16 glass
setblock ~-36 ~3 ~-16 torch
fill ~-39 ~-1 ~1 ~-33 ~-1 ~7 light_gray_terracotta
fill ~-39 ~0 ~1 ~-33 ~3 ~7 light_gray_terracotta hollow
fill ~-39 ~4 ~1 ~-33 ~4 ~7 nether_brick
setblock ~-36 ~0 ~1 air
setblock ~-36 ~1 ~1 air
setblock ~-33 ~2 ~4 glass
setblock ~-39 ~2 ~4 glass
setblock ~-36 ~3 ~4 torch
fill ~-39 ~-1 ~21 ~-33 ~-1 ~27 brown_terracotta
fill ~-39 ~0 ~21 ~-33 ~3 ~27 brown_terracotta hollow
fill ~-39 ~4 ~21 ~-33 ~4 ~27 spruce_planks
setblock ~-36 ~0 ~21 air
setblock ~-36 ~1 ~21 air
setblock ~-33 ~2 ~24 glass
setblock ~-39 ~2 ~24 glass
setblock ~-36 ~3 ~24 torch
fill ~-39 ~-1 ~41 ~-33 ~-1 ~47 oak_planks
fill ~-39 ~0 ~41 ~-33 ~3 ~47 oak_planks hollow
fill ~-39 ~4 ~41 ~-33 ~4 ~47 dark_oak_planks
setblock ~-36 ~0 ~41 air
setblock ~-36 ~1 ~41 air
setblock ~-33 ~2 ~44 glass
setblock ~-39 ~2 ~44 glass
setblock ~-36 ~3 ~44 torch
fill ~-39 ~-1 ~61 ~-33 ~-1 ~67 spruce_planks
fill ~-39 ~0 ~61 ~-33 ~3 ~67 spruce_planks hollow
fill ~-39 ~4 ~61 ~-33 ~4 ~67 brick_block
setblock ~-36 ~0 ~61 air
setblock ~-36 ~1 ~61 air
setblock ~-33 ~2 ~64 glass
setblock ~-39 ~2 ~64 glass
setblock ~-36 ~3 ~64 torch
fill ~-39 ~-1 ~81 ~-33 ~-1 ~87 birch_planks
fill ~-39 ~0 ~81 ~-33 ~3 ~87 birch_planks hollow
fill ~-39 ~4 ~81 ~-33 ~4 ~87 nether_brick
setblock ~-36 ~0 ~81 air
setblock ~-36 ~1 ~81 air
setblock ~-33 ~2 ~84 glass
setblock ~-39 ~2 ~84 glass
setblock ~-36 ~3 ~84 torch
fill ~-19 ~-1 ~-79 ~-13 ~-1 ~-73 white_terracotta
fill ~-19 ~0 ~-79 ~-13 ~3 ~-73 white_terracotta hollow
fill ~-19 ~4 ~-79 ~-13 ~4 ~-73 spruce_planks
setblock ~-16 ~0 ~-79 air
setblock ~-16 ~1 ~-79 air
setblock ~-13 ~2 ~-76 glass
setblock ~-19 ~2 ~-76 glass
setblock ~-16 ~3 ~-76 torch
fill ~-19 ~-1 ~-59 ~-13 ~-1 ~-53 light_gray_terracotta
fill ~-19 ~0 ~-59 ~-13 ~3 ~-53 light_gray_terracotta hollow
fill ~-19 ~4 ~-59 ~-13 ~4 ~-53 dark_oak_planks
setblock ~-16 ~0 ~-59 air
setblock ~-16 ~1 ~-59 air
setblock ~-13 ~2 ~-56 glass
setblock ~-19 ~2 ~-56 glass
setblock ~-16 ~3 ~-56 torch
fill ~-19 ~-1 ~-39 ~-13 ~-1 ~-33 brown_terracotta
fill ~-19 ~0 ~-39 ~-13 ~3 ~-33 brown_terracotta hollow
fill ~-19 ~4 ~-39 ~-13 ~4 ~-33 brick_block
setblock ~-16 ~0 ~-39 air
setblock ~-16 ~1 ~-39 air
setblock ~-13 ~2 ~-36 glass
setblock ~-19 ~2 ~-36 glass
setblock ~-16 ~3 ~-36 torch
fill ~-19 ~-1 ~21 ~-13 ~-1 ~27 oak_planks
fill ~-19 ~0 ~21 ~-13 ~3 ~27 oak_planks hollow
fill ~-19 ~4 ~21 ~-13 ~4 ~27 nether_brick
setblock ~-16 ~0 ~21 air
setblock ~-16 ~1 ~21 air
setblock ~-13 ~2 ~24 glass
setblock ~-19 ~2 ~24 glass
setblock ~-16 ~3 ~24 torch
fill ~-19 ~-1 ~41 ~-13 ~-1 ~47 spruce_planks
fill ~-19 ~0 ~41 ~-13 ~3 ~47 spruce_planks hollow
fill ~-19 ~4 ~41 ~-13 ~4 ~47 spruce_planks
setblock ~-16 ~0 ~41 air
setblock ~-16 ~1 ~41 air
setblock ~-13 ~2 ~44 glass
setblock ~-19 ~2 ~44 glass
setblock ~-16 ~3 ~44 torch
fill ~-19 ~-1 ~61 ~-13 ~-1 ~67 birch_planks
fill ~-19 ~0 ~61 ~-13 ~3 ~67 birch_planks hollow
fill ~-19 ~4 ~61 ~-13 ~4 ~67 dark_oak_planks
setblock ~-16 ~0 ~61 air
setblock ~-16 ~1 ~61 air
setblock ~-13 ~2 ~64 glass
setblock ~-19 ~2 ~64 glass
setblock ~-16 ~3 ~64 torch
fill ~-19 ~-1 ~81 ~-13 ~-1 ~87 white_terracotta
fill ~-19 ~0 ~81 ~-13 ~3 ~87 white_terracotta hollow
fill ~-19 ~4 ~81 ~-13 ~4 ~87 brick_block
setblock ~-16 ~0 ~81 air
setblock ~-16 ~1 ~81 air
setblock ~-13 ~2 ~84 glass
setblock ~-19 ~2 ~84 glass
setblock ~-16 ~3 ~84 torch
fill ~1 ~-1 ~-79 ~7 ~-1 ~-73 light_gray_terracotta
fill ~1 ~0 ~-79 ~7 ~3 ~-73 light_gray_terracotta hollow
fill ~1 ~4 ~-79 ~7 ~4 ~-73 nether_brick
setblock ~4 ~0 ~-79 air
setblock ~4 ~1 ~-79 air
setblock ~7 ~2 ~-76 glass
setblock ~1 ~2 ~-76 glass
setblock ~4 ~3 ~-76 torch
fill ~1 ~-1 ~-59 ~7 ~-1 ~-53 brown_terracotta
fill ~1 ~0 ~-59 ~7 ~3 ~-53 brown_terracotta hollow
fill ~1 ~4 ~-59 ~7 ~4 ~-53 spruce_planks
setblock ~4 ~0 ~-59 air
setblock ~4 ~1 ~-59 air
setblock ~7 ~2 ~-56 glass
setblock ~1 ~2 ~-56 glass
setblock ~4 ~3 ~-56 torch
fill ~1 ~-1 ~-39 ~7 ~-1 ~-33 oak_planks
fill ~1 ~0 ~-39 ~7 ~3 ~-33 oak_planks hollow
fill ~1 ~4 ~-39 ~7 ~4 ~-33 dark_oak_planks
setblock ~4 ~0 ~-39 air
setblock ~4 ~1 ~-39 air
setblock ~7 ~2 ~-36 glass
setblock ~1 ~2 ~-36 glass
setblock ~4 ~3 ~-36 torch
fill ~1 ~-1 ~21 ~7 ~-1 ~27 spruce_planks
fill ~1 ~0 ~21 ~7 ~3 ~27 spruce_planks hollow
fill ~1 ~4 ~21 ~7 ~4 ~27 brick_block
setblock ~4 ~0 ~21 air
setblock ~4 ~1 ~21 air
setblock ~7 ~2 ~24 glass
setblock ~1 ~2 ~24 glass
setblock ~4 ~3 ~24 torch
fill ~1 ~-1 ~41 ~7 ~-1 ~47 birch_planks
fill ~1 ~0 ~41 ~7 ~3 ~47 birch_planks hollow
fill ~1 ~4 ~41 ~7 ~4 ~47 nether_brick
setblock ~4 ~0 ~41 air
setblock ~4 ~1 ~41 air
setblock ~7 ~2 ~44 glass
setblock ~1 ~2 ~44 glass
setblock ~4 ~3 ~44 torch
fill ~1 ~-1 ~61 ~7 ~-1 ~67 white_terracotta
fill ~1 ~0 ~61 ~7 ~3 ~67 white_terracotta hollow
fill ~1 ~4 ~61 ~7 ~4 ~67 spruce_planks
setblock ~4 ~0 ~61 air
setblock ~4 ~1 ~61 air
setblock ~7 ~2 ~64 glass
setblock ~1 ~2 ~64 glass
setblock ~4 ~3 ~64 torch
fill ~1 ~-1 ~81 ~7 ~-1 ~87 light_gray_terracotta
fill ~1 ~0 ~81 ~7 ~3 ~87 light_gray_terracotta hollow
fill ~1 ~4 ~81 ~7 ~4 ~87 dark_oak_planks
setblock ~4 ~0 ~81 air
setblock ~4 ~1 ~81 air
setblock ~7 ~2 ~84 glass
setblock ~1 ~2 ~84 glass
setblock ~4 ~3 ~84 torch
fill ~21 ~-1 ~-79 ~27 ~-1 ~-73 brown_terracotta
fill ~21 ~0 ~-79 ~27 ~3 ~-73 brown_terracotta hollow
fill ~21 ~4 ~-79 ~27 ~4 ~-73 brick_block
setblock ~24 ~0 ~-79 air
setblock ~24 ~1 ~-79 air
setblock ~27 ~2 ~-76 glass
setblock ~21 ~2 ~-76 glass
setblock ~24 ~3 ~-76 torch
fill ~21 ~-1 ~-59 ~27 ~-1 ~-53 oak_planks
fill ~21 ~0 ~-59 ~27 ~3 ~-53 oak_planks hollow
fill ~21 ~4 ~-59 ~27 ~4 ~-53 nether_brick
setblock ~24 ~0 ~-59 air
setblock ~24 ~1 ~-59 air
setblock ~27 ~2 ~-56 glass
setblock ~21 ~2 ~-56 glass
setblock ~24 ~3 ~-56 torch
fill ~21 ~-1 ~-39 ~27 ~-1 ~-33 spruce_planks
fill ~21 ~0 ~-39 ~27 ~3 ~-33 spruce_planks hollow
fill ~21 ~4 ~-39 ~27 ~4 ~-33 spruce_planks
setblock ~24 ~0 ~-39 air
setblock ~24 ~1 ~-39 air
setblock ~27 ~2 ~-36 glass
setblock ~21 ~2 ~-36 glass
setblock ~24 ~3 ~-36 torch
fill ~21 ~-1 ~-19 ~27 ~-1 ~-13 birch_planks
fill ~21 ~0 ~-19 ~27 ~3 ~-13 birch_planks hollow
fill ~21 ~4 ~-19 ~27 ~4 ~-13 dark_oak_planks
setblock ~24 ~0 ~-19 air
setblock ~24 ~1 ~-19 air
setblock ~27 ~2 ~-16 glass
setblock ~21 ~2 ~-16 glass
setblock ~24 ~3 ~-16 torch
fill ~21 ~-1 ~1 ~27 ~-1 ~7 white_terracotta
fill ~21 ~0 ~1 ~27 ~3 ~7 white_terracotta hollow
fill ~21 ~4 ~1 ~27 ~4 ~7 brick_block
setblock ~24 ~0 ~1 air
setblock ~24 ~1 ~1 air
setblock ~27 ~2 ~4 glass
setblock ~21 ~2 ~4 glass
setblock ~24 ~3 ~4 torch
fill ~21 ~-1 ~21 ~27 ~-1 ~27 light_gray_terracotta
fill ~21 ~0 ~21 ~27 ~3 ~27 light_gray_terracotta hollow
fill ~21 ~4 ~21 ~27 ~4 ~27 nether_brick
setblock ~24 ~0 ~21 air
setblock ~24 ~1 ~21 air
setblock ~27 ~2 ~24 glass
setblock ~21 ~2 ~24 glass
setblock ~24 ~3 ~24 torch
fill ~21 ~-1 ~41 ~27 ~-1 ~47 brown_terracotta
fill ~21 ~0 ~41 ~27 ~3 ~47 brown_terracotta hollow
fill ~21 ~4 ~41 ~27 ~4 ~47 spruce_planks
setblock ~24 ~0 ~41 air
setblock ~24 ~1 ~41 air
setblock ~27 ~2 ~44 glass
setblock ~21 ~2 ~44 glass
setblock ~24 ~3 ~44 torch
fill ~21 ~-1 ~61 ~27 ~-1 ~67 oak_planks
fill ~21 ~0 ~61 ~27 ~3 ~67 oak_planks hollow
fill ~21 ~4 ~61 ~27 ~4 ~67 dark_oak_planks
setblock ~24 ~0 ~61 air
setblock ~24 ~1 ~61 air
setblock ~27 ~2 ~64 glass
setblock ~21 ~2 ~64 glass
setblock ~24 ~3 ~64 torch
fill ~21 ~-1 ~81 ~27 ~-1 ~87 spruce_planks
fill ~21 ~0 ~81 ~27 ~3 ~87 spruce_planks hollow
fill ~21 ~4 ~81 ~27 ~4 ~87 brick_block
setblock ~24 ~0 ~81 air
setblock ~24 ~1 ~81 air
setblock ~27 ~2 ~84 glass
setblock ~21 ~2 ~84 glass
setblock ~24 ~3 ~84 torch
fill ~41 ~-1 ~-79 ~47 ~-1 ~-73 birch_planks
fill ~41 ~0 ~-79 ~47 ~3 ~-73 birch_planks hollow
fill ~41 ~4 ~-79 ~47 ~4 ~-73 nether_brick
setblock ~44 ~0 ~-79 air
setblock ~44 ~1 ~-79 air
setblock ~47 ~2 ~-76 glass
setblock ~41 ~2 ~-76 glass
setblock ~44 ~3 ~-76 torch
fill ~41 ~-1 ~-59 ~47 ~-1 ~-53 white_terracotta
fill ~41 ~0 ~-59 ~47 ~3 ~-53 white_terracotta hollow
fill ~41 ~4 ~-59 ~47 ~4 ~-53 spruce_planks
setblock ~44 ~0 ~-59 air
setblock ~44 ~1 ~-59 air
setblock ~47 ~2 ~-56 glass
setblock ~41 ~2 ~-56 glass
setblock ~44 ~3 ~-56 torch
fill ~41 ~-1 ~-39 ~47 ~-1 ~-33 light_gray_terracotta
fill ~41 ~0 ~-39 ~47 ~3 ~-33 light_gray_terracotta hollow
fill ~41 ~4 ~-39 ~47 ~4 ~-33 dark_oak_planks
setblock ~44 ~0 ~-39 air
setblock ~44 ~1 ~-39 air
setblock ~47 ~2 ~-36 glass
setblock ~41 ~2 ~-36 glass
setblock ~44 ~3 ~-36 torch
fill ~41 ~-1 ~-19 ~47 ~-1 ~-13 brown_terracotta
fill ~41 ~0 ~-19 ~47 ~3 ~-13 brown_terracotta hollow
fill ~41 ~4 ~-19 ~47 ~4 ~-13 brick_block
setblock ~44 ~0 ~-19 air
setblock ~44 ~1 ~-19 air
setblock ~47 ~2 ~-16 glass
setblock ~41 ~2 ~-16 glass
setblock ~44 ~3 ~-16 torch
fill ~41 ~-1 ~1 ~47 ~-1 ~7 oak_planks
fill ~41 ~0 ~1 ~47 ~3 ~7 oak_planks hollow
fill ~41 ~4 ~1 ~47 ~4 ~7 nether_brick
setblock ~44 ~0 ~1 air
setblock ~44 ~1 ~1 air
setblock ~47 ~2 ~4 glass
setblock ~41 ~2 ~4 glass
setblock ~44 ~3 ~4 torch
fill ~41 ~-1 ~21 ~47 ~-1 ~27 spruce_planks
fill ~41 ~0 ~21 ~47 ~3 ~27 spruce_planks hollow
fill ~41 ~4 ~21 ~47 ~4 ~27 spruce_planks
setblock ~44 ~0 ~21 air
setblock ~44 ~1 ~21 air
setblock ~47 ~2 ~24 glass
setblock ~41 ~2 ~24 glass
setblock ~44 ~3 ~24 torch
fill ~41 ~-1 ~41 ~47 ~-1 ~47 birch_planks
fill ~41 ~0 ~41 ~47 ~3 ~47 birch_planks hollow
fill ~41 ~4 ~41 ~47 ~4 ~47 dark_oak_planks
setblock ~44 ~0 ~41 air
setblock ~44 ~1 ~41 air
setblock ~47 ~2 ~44 glass
setblock ~41 ~2 ~44 glass
setblock ~44 ~3 ~44 torch
fill ~41 ~-1 ~61 ~47 ~-1 ~67 white_terracotta
fill ~41 ~0 ~61 ~47 ~3 ~67 white_terracotta hollow
fill ~41 ~4 ~61 ~47 ~4 ~67 brick_block
setblock ~44 ~0 ~61 air
setblock ~44 ~1 ~61 air
setblock ~47 ~2 ~64 glass
setblock ~41 ~2 ~64 glass
setblock ~44 ~3 ~64 torch
fill ~41 ~-1 ~81 ~47 ~-1 ~87 light_gray_terracotta
fill ~41 ~0 ~81 ~47 ~3 ~87 light_gray_terracotta hollow
fill ~41 ~4 ~81 ~47 ~4 ~87 nether_brick
setblock ~44 ~0 ~81 air
setblock ~44 ~1 ~81 air
setblock ~47 ~2 ~84 glass
setblock ~41 ~2 ~84 glass
setblock ~44 ~3 ~84 torch
fill ~61 ~-1 ~-79 ~67 ~-1 ~-73 brown_terracotta
fill ~61 ~0 ~-79 ~67 ~3 ~-73 brown_terracotta hollow
fill ~61 ~4 ~-79 ~67 ~4 ~-73 spruce_planks
setblock ~64 ~0 ~-79 air
setblock ~64 ~1 ~-79 air
setblock ~67 ~2 ~-76 glass
setblock ~61 ~2 ~-76 glass
setblock ~64 ~3 ~-76 torch
fill ~61 ~-1 ~-59 ~67 ~-1 ~-53 oak_planks
fill ~61 ~0 ~-59 ~67 ~3 ~-53 oak_planks hollow
fill ~61 ~4 ~-59 ~67 ~4 ~-53 dark_oak_planks
setblock ~64 ~0 ~-59 air
setblock ~64 ~1 ~-59 air
setblock ~67 ~2 ~-56 glass
setblock ~61 ~2 ~-56 glass
setblock ~64 ~3 ~-56 torch
fill ~61 ~-1 ~-39 ~67 ~-1 ~-33 spruce_planks
fill ~61 ~0 ~-39 ~67 ~3 ~-33 spruce_planks hollow
fill ~61 ~4 ~-39 ~67 ~4 ~-33 brick_block
setblock ~64 ~0 ~-39 air
setblock ~64 ~1 ~-39 air
setblock ~67 ~2 ~-36 glass
setblock ~61 ~2 ~-36 glass
setblock ~64 ~3 ~-36 torch
fill ~61 ~-1 ~-19 ~67 ~-1 ~-13 birch_planks
fill ~61 ~0 ~-19 ~67 ~3 ~-13 birch_planks hollow
fill ~61 ~4 ~-19 ~67 ~4 ~-13 nether_brick
setblock ~64 ~0 ~-19 air
setblock ~64 ~1 ~-19 air
setblock ~67 ~2 ~-16 glass
setblock ~61 ~2 ~-16 glass
setblock ~64 ~3 ~-16 torch
fill ~61 ~-1 ~1 ~67 ~-1 ~7 white_terracotta
fill ~61 ~0 ~1 ~67 ~3 ~7 white_terracotta hollow
fill ~61 ~4 ~1 ~67 ~4 ~7 spruce_planks
setblock ~64 ~0 ~1 air
setblock ~64 ~1 ~1 air
setblock ~67 ~2 ~4 glass
setblock ~61 ~2 ~4 glass
setblock ~64 ~3 ~4 torch
fill ~61 ~-1 ~21 ~67 ~-1 ~27 light_gray_terracotta
fill ~61 ~0 ~21 ~67 ~3 ~27 light_gray_terracotta hollow
fill ~61 ~4 ~21 ~67 ~4 ~27 dark_oak_planks
setblock ~64 ~0 ~21 air
setblock ~64 ~1 ~21 air
setblock ~67 ~2 ~24 glass
setblock ~61 ~2 ~24 glass
setblock ~64 ~3 ~24 torch
fill ~61 ~-1 ~41 ~67 ~-1 ~47 brown_terracotta
fill ~61 ~0 ~41 ~67 ~3 ~47 brown_terracotta hollow
fill ~61 ~4 ~41 ~67 ~4 ~47 brick_block
setblock ~64 ~0 ~41 air
setblock ~64 ~1 ~41 air
setblock ~67 ~2 ~44 glass
setblock ~61 ~2 ~44 glass
setblock ~64 ~3 ~44 torch
fill ~61 ~-1 ~61 ~67 ~-1 ~67 oak_planks
fill ~61 ~0 ~61 ~67 ~3 ~67 oak_planks hollow
fill ~61 ~4 ~61 ~67 ~4 ~67 nether_brick
setblock ~64 ~0 ~61 air
setblock ~64 ~1 ~61 air
setblock ~67 ~2 ~64 glass
setblock ~61 ~2 ~64 glass
setblock ~64 ~3 ~64 torch
fill ~61 ~-1 ~81 ~67 ~-1 ~87 spruce_planks
fill ~61 ~0 ~81 ~67 ~3 ~87 spruce_planks hollow
fill ~61 ~4 ~81 ~67 ~4 ~87 spruce_planks
setblock ~64 ~0 ~81 air
setblock ~64 ~1 ~81 air
setblock ~67 ~2 ~84 glass
setblock ~61 ~2 ~84 glass
setblock ~64 ~3 ~84 torch
fill ~81 ~-1 ~-79 ~87 ~-1 ~-73 birch_planks
fill ~81 ~0 ~-79 ~87 ~3 ~-73 birch_planks hollow
fill ~81 ~4 ~-79 ~87 ~4 ~-73 dark_oak_planks
setblock ~84 ~0 ~-79 air
setblock ~84 ~1 ~-79 air
setblock ~87 ~2 ~-76 glass
setblock ~81 ~2 ~-76 glass
setblock ~84 ~3 ~-76 torch
fill ~81 ~-1 ~-59 ~87 ~-1 ~-53 white_terracotta
fill ~81 ~0 ~-59 ~87 ~3 ~-53 white_terracotta hollow
fill ~81 ~4 ~-59 ~87 ~4 ~-53 brick_block
setblock ~84 ~0 ~-59 air
setblock ~84 ~1 ~-59 air
setblock ~87 ~2 ~-56 glass
setblock ~81 ~2 ~-56 glass
setblock ~84 ~3 ~-56 torch
fill ~81 ~-1 ~-39 ~87 ~-1 ~-33 light_gray_terracotta
fill ~81 ~0 ~-39 ~87 ~3 ~-33 light_gray_terracotta hollow
fill ~81 ~4 ~-39 ~87 ~4 ~-33 nether_brick
setblock ~84 ~0 ~-39 air
setblock ~84 ~1 ~-39 air
setblock ~87 ~2 ~-36 glass
setblock ~81 ~2 ~-36 glass
setblock ~84 ~3 ~-36 torch
fill ~81 ~-1 ~-19 ~87 ~-1 ~-13 brown_terracotta
fill ~81 ~0 ~-19 ~87 ~3 ~-13 brown_terracotta hollow
fill ~81 ~4 ~-19 ~87 ~4 ~-13 spruce_planks
setblock ~84 ~0 ~-19 air
setblock ~84 ~1 ~-19 air
setblock ~87 ~2 ~-16 glass
setblock ~81 ~2 ~-16 glass
setblock ~84 ~3 ~-16 torch
fill ~81 ~-1 ~1 ~87 ~-1 ~7 oak_planks
fill ~81 ~0 ~1 ~87 ~3 ~7 oak_planks hollow
fill ~81 ~4 ~1 ~87 ~4 ~7 dark_oak_planks
setblock ~84 ~0 ~1 air
setblock ~84 ~1 ~1 air
setblock ~87 ~2 ~4 glass
setblock ~81 ~2 ~4 glass
setblock ~84 ~3 ~4 torch
fill ~81 ~-1 ~21 ~87 ~-1 ~27 spruce_planks
fill ~81 ~0 ~21 ~87 ~3 ~27 spruce_planks hollow
fill ~81 ~4 ~21 ~87 ~4 ~27 brick_block
setblock ~84 ~0 ~21 air
setblock ~84 ~1 ~21 air
setblock ~87 ~2 ~24 glass
setblock ~81 ~2 ~24 glass
setblock ~84 ~3 ~24 torch
fill ~81 ~-1 ~41 ~87 ~-1 ~47 birch_planks
fill ~81 ~0 ~41 ~87 ~3 ~47 birch_planks hollow
fill ~81 ~4 ~41 ~87 ~4 ~47 nether_brick
setblock ~84 ~0 ~41 air
setblock ~84 ~1 ~41 air
setblock ~87 ~2 ~44 glass
setblock ~81 ~2 ~44 glass
setblock ~84 ~3 ~44 torch
fill ~81 ~-1 ~61 ~87 ~-1 ~67 white_terracotta
fill ~81 ~0 ~61 ~87 ~3 ~67 white_terracotta hollow
fill ~81 ~4 ~61 ~87 ~4 ~67 spruce_planks
setblock ~84 ~0 ~61 air
setblock ~84 ~1 ~61 air
setblock ~87 ~2 ~64 glass
setblock ~81 ~2 ~64 glass
setblock ~84 ~3 ~64 torch
fill ~81 ~-1 ~81 ~87 ~-1 ~87 light_gray_terracotta
fill ~81 ~0 ~81 ~87 ~3 ~87 light_gray_terracotta hollow
fill ~81 ~4 ~81 ~87 ~4 ~87 dark_oak_planks
setblock ~84 ~0 ~81 air
setblock ~84 ~1 ~81 air
setblock ~87 ~2 ~84 glass
setblock ~81 ~2 ~84 glass
setblock ~84 ~3 ~84 torch
# Dorpelingen
summon villager_v2 ~-76 ~1 ~-72
summon villager_v2 ~-76 ~1 ~-32
summon villager_v2 ~-76 ~1 ~8
summon villager_v2 ~-76 ~1 ~48
summon villager_v2 ~-76 ~1 ~88
summon villager_v2 ~-56 ~1 ~-52
summon villager_v2 ~-56 ~1 ~-12
summon villager_v2 ~-56 ~1 ~28
summon villager_v2 ~-56 ~1 ~68
summon villager_v2 ~-36 ~1 ~-72
summon villager_v2 ~-36 ~1 ~-32
summon villager_v2 ~-36 ~1 ~8
summon villager_v2 ~-36 ~1 ~48
summon villager_v2 ~-36 ~1 ~88
summon villager_v2 ~-16 ~1 ~-52
summon villager_v2 ~-16 ~1 ~28
summon villager_v2 ~-16 ~1 ~68
summon villager_v2 ~4 ~1 ~-72
summon villager_v2 ~4 ~1 ~-32
summon villager_v2 ~4 ~1 ~48
summon villager_v2 ~4 ~1 ~88
summon villager_v2 ~24 ~1 ~-52
summon villager_v2 ~24 ~1 ~-12
summon villager_v2 ~24 ~1 ~28
summon villager_v2 ~24 ~1 ~68
summon villager_v2 ~44 ~1 ~-72
summon villager_v2 ~44 ~1 ~-32
summon villager_v2 ~44 ~1 ~8
summon villager_v2 ~44 ~1 ~48
summon villager_v2 ~44 ~1 ~88
summon villager_v2 ~64 ~1 ~-52
summon villager_v2 ~64 ~1 ~-12
summon villager_v2 ~64 ~1 ~28
summon villager_v2 ~64 ~1 ~68
summon villager_v2 ~84 ~1 ~-72
summon villager_v2 ~84 ~1 ~-32
summon villager_v2 ~84 ~1 ~8
summon villager_v2 ~84 ~1 ~48
summon villager_v2 ~84 ~1 ~88
# klaar
