# ==========================================================
# BAAS VAN HET DORP - compact dorp rondom de speler
# Gegenereerd door scripts/generate_dorpsbaas.py
# ==========================================================
# Ruimte vrijmaken + grond
fill ~-44 ~0 ~-44 ~-17 ~20 ~-17 air
fill ~-44 ~0 ~-16 ~-17 ~20 ~11 air
fill ~-44 ~0 ~12 ~-17 ~20 ~39 air
fill ~-44 ~0 ~40 ~-17 ~20 ~44 air
fill ~-16 ~0 ~-44 ~11 ~20 ~-17 air
fill ~-16 ~0 ~-16 ~11 ~20 ~11 air
fill ~-16 ~0 ~12 ~11 ~20 ~39 air
fill ~-16 ~0 ~40 ~11 ~20 ~44 air
fill ~12 ~0 ~-44 ~39 ~20 ~-17 air
fill ~12 ~0 ~-16 ~39 ~20 ~11 air
fill ~12 ~0 ~12 ~39 ~20 ~39 air
fill ~12 ~0 ~40 ~39 ~20 ~44 air
fill ~40 ~0 ~-44 ~44 ~20 ~-17 air
fill ~40 ~0 ~-16 ~44 ~20 ~11 air
fill ~40 ~0 ~12 ~44 ~20 ~39 air
fill ~40 ~0 ~40 ~44 ~20 ~44 air
fill ~-44 ~-1 ~-44 ~-17 ~-1 ~-17 grass_block
fill ~-44 ~-1 ~-16 ~-17 ~-1 ~11 grass_block
fill ~-44 ~-1 ~12 ~-17 ~-1 ~39 grass_block
fill ~-44 ~-1 ~40 ~-17 ~-1 ~44 grass_block
fill ~-16 ~-1 ~-44 ~11 ~-1 ~-17 grass_block
fill ~-16 ~-1 ~-16 ~11 ~-1 ~11 grass_block
fill ~-16 ~-1 ~12 ~11 ~-1 ~39 grass_block
fill ~-16 ~-1 ~40 ~11 ~-1 ~44 grass_block
fill ~12 ~-1 ~-44 ~39 ~-1 ~-17 grass_block
fill ~12 ~-1 ~-16 ~39 ~-1 ~11 grass_block
fill ~12 ~-1 ~12 ~39 ~-1 ~39 grass_block
fill ~12 ~-1 ~40 ~39 ~-1 ~44 grass_block
fill ~40 ~-1 ~-44 ~44 ~-1 ~-17 grass_block
fill ~40 ~-1 ~-16 ~44 ~-1 ~11 grass_block
fill ~40 ~-1 ~12 ~44 ~-1 ~39 grass_block
fill ~40 ~-1 ~40 ~44 ~-1 ~44 grass_block
fill ~-44 ~-2 ~-44 ~-17 ~-2 ~-17 dirt
fill ~-44 ~-2 ~-16 ~-17 ~-2 ~11 dirt
fill ~-44 ~-2 ~12 ~-17 ~-2 ~39 dirt
fill ~-44 ~-2 ~40 ~-17 ~-2 ~44 dirt
fill ~-16 ~-2 ~-44 ~11 ~-2 ~-17 dirt
fill ~-16 ~-2 ~-16 ~11 ~-2 ~11 dirt
fill ~-16 ~-2 ~12 ~11 ~-2 ~39 dirt
fill ~-16 ~-2 ~40 ~11 ~-2 ~44 dirt
fill ~12 ~-2 ~-44 ~39 ~-2 ~-17 dirt
fill ~12 ~-2 ~-16 ~39 ~-2 ~11 dirt
fill ~12 ~-2 ~12 ~39 ~-2 ~39 dirt
fill ~12 ~-2 ~40 ~39 ~-2 ~44 dirt
fill ~40 ~-2 ~-44 ~44 ~-2 ~-17 dirt
fill ~40 ~-2 ~-16 ~44 ~-2 ~11 dirt
fill ~40 ~-2 ~12 ~44 ~-2 ~39 dirt
fill ~40 ~-2 ~40 ~44 ~-2 ~44 dirt
# Wegen (plat, vrij voor de auto)
fill ~-37 ~-1 ~-44 ~-35 ~-1 ~-17 stone
fill ~-37 ~-1 ~-16 ~-35 ~-1 ~11 stone
fill ~-37 ~-1 ~12 ~-35 ~-1 ~39 stone
fill ~-37 ~-1 ~40 ~-35 ~-1 ~44 stone
fill ~-44 ~-1 ~-37 ~-17 ~-1 ~-35 stone
fill ~-16 ~-1 ~-37 ~11 ~-1 ~-35 stone
fill ~12 ~-1 ~-37 ~39 ~-1 ~-35 stone
fill ~40 ~-1 ~-37 ~44 ~-1 ~-35 stone
fill ~-21 ~-1 ~-44 ~-19 ~-1 ~-17 stone
fill ~-21 ~-1 ~-16 ~-19 ~-1 ~11 stone
fill ~-21 ~-1 ~12 ~-19 ~-1 ~39 stone
fill ~-21 ~-1 ~40 ~-19 ~-1 ~44 stone
fill ~-44 ~-1 ~-21 ~-17 ~-1 ~-19 stone
fill ~-16 ~-1 ~-21 ~11 ~-1 ~-19 stone
fill ~12 ~-1 ~-21 ~39 ~-1 ~-19 stone
fill ~40 ~-1 ~-21 ~44 ~-1 ~-19 stone
fill ~-5 ~-1 ~-44 ~-3 ~-1 ~-17 stone
fill ~-5 ~-1 ~-16 ~-3 ~-1 ~11 stone
fill ~-5 ~-1 ~12 ~-3 ~-1 ~39 stone
fill ~-5 ~-1 ~40 ~-3 ~-1 ~44 stone
fill ~-44 ~-1 ~-5 ~-17 ~-1 ~-3 stone
fill ~-16 ~-1 ~-5 ~11 ~-1 ~-3 stone
fill ~12 ~-1 ~-5 ~39 ~-1 ~-3 stone
fill ~40 ~-1 ~-5 ~44 ~-1 ~-3 stone
fill ~11 ~-1 ~-44 ~13 ~-1 ~-17 stone
fill ~11 ~-1 ~-16 ~13 ~-1 ~11 stone
fill ~11 ~-1 ~12 ~13 ~-1 ~39 stone
fill ~11 ~-1 ~40 ~13 ~-1 ~44 stone
fill ~-44 ~-1 ~11 ~-17 ~-1 ~13 stone
fill ~-16 ~-1 ~11 ~11 ~-1 ~13 stone
fill ~12 ~-1 ~11 ~39 ~-1 ~13 stone
fill ~40 ~-1 ~11 ~44 ~-1 ~13 stone
fill ~27 ~-1 ~-44 ~29 ~-1 ~-17 stone
fill ~27 ~-1 ~-16 ~29 ~-1 ~11 stone
fill ~27 ~-1 ~12 ~29 ~-1 ~39 stone
fill ~27 ~-1 ~40 ~29 ~-1 ~44 stone
fill ~-44 ~-1 ~27 ~-17 ~-1 ~29 stone
fill ~-16 ~-1 ~27 ~11 ~-1 ~29 stone
fill ~12 ~-1 ~27 ~39 ~-1 ~29 stone
fill ~40 ~-1 ~27 ~44 ~-1 ~29 stone
# Dorpshuisjes (met winkelgevels)
fill ~-33 ~-1 ~-33 ~-27 ~-1 ~-27 oak_planks
fill ~-33 ~0 ~-33 ~-27 ~3 ~-33 oak_planks
fill ~-33 ~0 ~-27 ~-27 ~3 ~-27 oak_planks
fill ~-33 ~0 ~-33 ~-33 ~3 ~-27 oak_planks
fill ~-27 ~0 ~-33 ~-27 ~3 ~-27 oak_planks
fill ~-33 ~4 ~-33 ~-27 ~4 ~-27 dark_oak_planks
fill ~-33 ~5 ~-33 ~-27 ~5 ~-27 dark_oak_planks
setblock ~-30 ~0 ~-27 air
setblock ~-30 ~1 ~-27 air
setblock ~-32 ~1 ~-27 glass
setblock ~-28 ~1 ~-27 glass
fill ~-33 ~2 ~-26 ~-27 ~2 ~-26 red_wool
setblock ~-33 ~3 ~-33 torch
setblock ~-27 ~3 ~-33 torch
setblock ~-30 ~3 ~-30 lantern
fill ~-33 ~-1 ~-17 ~-27 ~-1 ~-11 spruce_planks
fill ~-33 ~0 ~-17 ~-27 ~3 ~-17 spruce_planks
fill ~-33 ~0 ~-11 ~-27 ~3 ~-11 spruce_planks
fill ~-33 ~0 ~-17 ~-33 ~3 ~-11 spruce_planks
fill ~-27 ~0 ~-17 ~-27 ~3 ~-11 spruce_planks
fill ~-33 ~4 ~-17 ~-27 ~4 ~-11 brick_block
fill ~-33 ~5 ~-17 ~-27 ~5 ~-11 brick_block
setblock ~-30 ~0 ~-11 air
setblock ~-30 ~1 ~-11 air
setblock ~-32 ~1 ~-11 glass
setblock ~-28 ~1 ~-11 glass
fill ~-33 ~2 ~-10 ~-27 ~2 ~-10 blue_wool
setblock ~-33 ~3 ~-17 torch
setblock ~-27 ~3 ~-17 torch
setblock ~-30 ~3 ~-14 lantern
fill ~-33 ~-1 ~-1 ~-27 ~-1 ~5 birch_planks
fill ~-33 ~0 ~-1 ~-27 ~3 ~-1 birch_planks
fill ~-33 ~0 ~5 ~-27 ~3 ~5 birch_planks
fill ~-33 ~0 ~-1 ~-33 ~3 ~5 birch_planks
fill ~-27 ~0 ~-1 ~-27 ~3 ~5 birch_planks
fill ~-33 ~4 ~-1 ~-27 ~4 ~5 nether_brick
fill ~-33 ~5 ~-1 ~-27 ~5 ~5 nether_brick
setblock ~-30 ~0 ~5 air
setblock ~-30 ~1 ~5 air
setblock ~-32 ~1 ~5 glass
setblock ~-28 ~1 ~5 glass
fill ~-33 ~2 ~6 ~-27 ~2 ~6 green_wool
setblock ~-33 ~3 ~-1 torch
setblock ~-27 ~3 ~-1 torch
setblock ~-30 ~3 ~2 lantern
fill ~-33 ~-1 ~15 ~-27 ~-1 ~21 white_terracotta
fill ~-33 ~0 ~15 ~-27 ~3 ~15 white_terracotta
fill ~-33 ~0 ~21 ~-27 ~3 ~21 white_terracotta
fill ~-33 ~0 ~15 ~-33 ~3 ~21 white_terracotta
fill ~-27 ~0 ~15 ~-27 ~3 ~21 white_terracotta
fill ~-33 ~4 ~15 ~-27 ~4 ~21 stone_bricks
fill ~-33 ~5 ~15 ~-27 ~5 ~21 stone_bricks
setblock ~-30 ~0 ~21 air
setblock ~-30 ~1 ~21 air
setblock ~-32 ~1 ~21 glass
setblock ~-28 ~1 ~21 glass
fill ~-33 ~2 ~22 ~-27 ~2 ~22 yellow_wool
setblock ~-33 ~3 ~15 torch
setblock ~-27 ~3 ~15 torch
setblock ~-30 ~3 ~18 lantern
fill ~-33 ~-1 ~31 ~-27 ~-1 ~37 light_gray_terracotta
fill ~-33 ~0 ~31 ~-27 ~3 ~31 light_gray_terracotta
fill ~-33 ~0 ~37 ~-27 ~3 ~37 light_gray_terracotta
fill ~-33 ~0 ~31 ~-33 ~3 ~37 light_gray_terracotta
fill ~-27 ~0 ~31 ~-27 ~3 ~37 light_gray_terracotta
fill ~-33 ~4 ~31 ~-27 ~4 ~37 dark_oak_planks
fill ~-33 ~5 ~31 ~-27 ~5 ~37 dark_oak_planks
setblock ~-30 ~0 ~37 air
setblock ~-30 ~1 ~37 air
setblock ~-32 ~1 ~37 glass
setblock ~-28 ~1 ~37 glass
fill ~-33 ~2 ~38 ~-27 ~2 ~38 orange_wool
setblock ~-33 ~3 ~31 torch
setblock ~-27 ~3 ~31 torch
setblock ~-30 ~3 ~34 lantern
fill ~-17 ~-1 ~-33 ~-11 ~-1 ~-27 brown_terracotta
fill ~-17 ~0 ~-33 ~-11 ~3 ~-33 brown_terracotta
fill ~-17 ~0 ~-27 ~-11 ~3 ~-27 brown_terracotta
fill ~-17 ~0 ~-33 ~-17 ~3 ~-27 brown_terracotta
fill ~-11 ~0 ~-33 ~-11 ~3 ~-27 brown_terracotta
fill ~-17 ~4 ~-33 ~-11 ~4 ~-27 brick_block
fill ~-17 ~5 ~-33 ~-11 ~5 ~-27 brick_block
setblock ~-14 ~0 ~-27 air
setblock ~-14 ~1 ~-27 air
setblock ~-16 ~1 ~-27 glass
setblock ~-12 ~1 ~-27 glass
fill ~-17 ~2 ~-26 ~-11 ~2 ~-26 red_wool
setblock ~-17 ~3 ~-33 torch
setblock ~-11 ~3 ~-33 torch
setblock ~-14 ~3 ~-30 lantern
fill ~-17 ~-1 ~31 ~-11 ~-1 ~37 oak_planks
fill ~-17 ~0 ~31 ~-11 ~3 ~31 oak_planks
fill ~-17 ~0 ~37 ~-11 ~3 ~37 oak_planks
fill ~-17 ~0 ~31 ~-17 ~3 ~37 oak_planks
fill ~-11 ~0 ~31 ~-11 ~3 ~37 oak_planks
fill ~-17 ~4 ~31 ~-11 ~4 ~37 nether_brick
fill ~-17 ~5 ~31 ~-11 ~5 ~37 nether_brick
setblock ~-14 ~0 ~37 air
setblock ~-14 ~1 ~37 air
setblock ~-16 ~1 ~37 glass
setblock ~-12 ~1 ~37 glass
fill ~-17 ~2 ~38 ~-11 ~2 ~38 blue_wool
setblock ~-17 ~3 ~31 torch
setblock ~-11 ~3 ~31 torch
setblock ~-14 ~3 ~34 lantern
fill ~-1 ~-1 ~-33 ~5 ~-1 ~-27 spruce_planks
fill ~-1 ~0 ~-33 ~5 ~3 ~-33 spruce_planks
fill ~-1 ~0 ~-27 ~5 ~3 ~-27 spruce_planks
fill ~-1 ~0 ~-33 ~-1 ~3 ~-27 spruce_planks
fill ~5 ~0 ~-33 ~5 ~3 ~-27 spruce_planks
fill ~-1 ~4 ~-33 ~5 ~4 ~-27 stone_bricks
fill ~-1 ~5 ~-33 ~5 ~5 ~-27 stone_bricks
setblock ~2 ~0 ~-27 air
setblock ~2 ~1 ~-27 air
setblock ~0 ~1 ~-27 glass
setblock ~4 ~1 ~-27 glass
fill ~-1 ~2 ~-26 ~5 ~2 ~-26 green_wool
setblock ~-1 ~3 ~-33 torch
setblock ~5 ~3 ~-33 torch
setblock ~2 ~3 ~-30 lantern
fill ~-1 ~-1 ~31 ~5 ~-1 ~37 birch_planks
fill ~-1 ~0 ~31 ~5 ~3 ~31 birch_planks
fill ~-1 ~0 ~37 ~5 ~3 ~37 birch_planks
fill ~-1 ~0 ~31 ~-1 ~3 ~37 birch_planks
fill ~5 ~0 ~31 ~5 ~3 ~37 birch_planks
fill ~-1 ~4 ~31 ~5 ~4 ~37 dark_oak_planks
fill ~-1 ~5 ~31 ~5 ~5 ~37 dark_oak_planks
setblock ~2 ~0 ~37 air
setblock ~2 ~1 ~37 air
setblock ~0 ~1 ~37 glass
setblock ~4 ~1 ~37 glass
fill ~-1 ~2 ~38 ~5 ~2 ~38 yellow_wool
setblock ~-1 ~3 ~31 torch
setblock ~5 ~3 ~31 torch
setblock ~2 ~3 ~34 lantern
fill ~15 ~-1 ~-33 ~21 ~-1 ~-27 white_terracotta
fill ~15 ~0 ~-33 ~21 ~3 ~-33 white_terracotta
fill ~15 ~0 ~-27 ~21 ~3 ~-27 white_terracotta
fill ~15 ~0 ~-33 ~15 ~3 ~-27 white_terracotta
fill ~21 ~0 ~-33 ~21 ~3 ~-27 white_terracotta
fill ~15 ~4 ~-33 ~21 ~4 ~-27 brick_block
fill ~15 ~5 ~-33 ~21 ~5 ~-27 brick_block
setblock ~18 ~0 ~-27 air
setblock ~18 ~1 ~-27 air
setblock ~16 ~1 ~-27 glass
setblock ~20 ~1 ~-27 glass
fill ~15 ~2 ~-26 ~21 ~2 ~-26 orange_wool
setblock ~15 ~3 ~-33 torch
setblock ~21 ~3 ~-33 torch
setblock ~18 ~3 ~-30 lantern
fill ~15 ~-1 ~31 ~21 ~-1 ~37 light_gray_terracotta
fill ~15 ~0 ~31 ~21 ~3 ~31 light_gray_terracotta
fill ~15 ~0 ~37 ~21 ~3 ~37 light_gray_terracotta
fill ~15 ~0 ~31 ~15 ~3 ~37 light_gray_terracotta
fill ~21 ~0 ~31 ~21 ~3 ~37 light_gray_terracotta
fill ~15 ~4 ~31 ~21 ~4 ~37 nether_brick
fill ~15 ~5 ~31 ~21 ~5 ~37 nether_brick
setblock ~18 ~0 ~37 air
setblock ~18 ~1 ~37 air
setblock ~16 ~1 ~37 glass
setblock ~20 ~1 ~37 glass
fill ~15 ~2 ~38 ~21 ~2 ~38 red_wool
setblock ~15 ~3 ~31 torch
setblock ~21 ~3 ~31 torch
setblock ~18 ~3 ~34 lantern
fill ~31 ~-1 ~-33 ~37 ~-1 ~-27 brown_terracotta
fill ~31 ~0 ~-33 ~37 ~3 ~-33 brown_terracotta
fill ~31 ~0 ~-27 ~37 ~3 ~-27 brown_terracotta
fill ~31 ~0 ~-33 ~31 ~3 ~-27 brown_terracotta
fill ~37 ~0 ~-33 ~37 ~3 ~-27 brown_terracotta
fill ~31 ~4 ~-33 ~37 ~4 ~-27 stone_bricks
fill ~31 ~5 ~-33 ~37 ~5 ~-27 stone_bricks
setblock ~34 ~0 ~-27 air
setblock ~34 ~1 ~-27 air
setblock ~32 ~1 ~-27 glass
setblock ~36 ~1 ~-27 glass
fill ~31 ~2 ~-26 ~37 ~2 ~-26 blue_wool
setblock ~31 ~3 ~-33 torch
setblock ~37 ~3 ~-33 torch
setblock ~34 ~3 ~-30 lantern
fill ~31 ~-1 ~-17 ~37 ~-1 ~-11 oak_planks
fill ~31 ~0 ~-17 ~37 ~3 ~-17 oak_planks
fill ~31 ~0 ~-11 ~37 ~3 ~-11 oak_planks
fill ~31 ~0 ~-17 ~31 ~3 ~-11 oak_planks
fill ~37 ~0 ~-17 ~37 ~3 ~-11 oak_planks
fill ~31 ~4 ~-17 ~37 ~4 ~-11 dark_oak_planks
fill ~31 ~5 ~-17 ~37 ~5 ~-11 dark_oak_planks
setblock ~34 ~0 ~-11 air
setblock ~34 ~1 ~-11 air
setblock ~32 ~1 ~-11 glass
setblock ~36 ~1 ~-11 glass
fill ~31 ~2 ~-10 ~37 ~2 ~-10 green_wool
setblock ~31 ~3 ~-17 torch
setblock ~37 ~3 ~-17 torch
setblock ~34 ~3 ~-14 lantern
fill ~31 ~-1 ~-1 ~37 ~-1 ~5 spruce_planks
fill ~31 ~0 ~-1 ~37 ~3 ~-1 spruce_planks
fill ~31 ~0 ~5 ~37 ~3 ~5 spruce_planks
fill ~31 ~0 ~-1 ~31 ~3 ~5 spruce_planks
fill ~37 ~0 ~-1 ~37 ~3 ~5 spruce_planks
fill ~31 ~4 ~-1 ~37 ~4 ~5 brick_block
fill ~31 ~5 ~-1 ~37 ~5 ~5 brick_block
setblock ~34 ~0 ~5 air
setblock ~34 ~1 ~5 air
setblock ~32 ~1 ~5 glass
setblock ~36 ~1 ~5 glass
fill ~31 ~2 ~6 ~37 ~2 ~6 yellow_wool
setblock ~31 ~3 ~-1 torch
setblock ~37 ~3 ~-1 torch
setblock ~34 ~3 ~2 lantern
fill ~31 ~-1 ~15 ~37 ~-1 ~21 birch_planks
fill ~31 ~0 ~15 ~37 ~3 ~15 birch_planks
fill ~31 ~0 ~21 ~37 ~3 ~21 birch_planks
fill ~31 ~0 ~15 ~31 ~3 ~21 birch_planks
fill ~37 ~0 ~15 ~37 ~3 ~21 birch_planks
fill ~31 ~4 ~15 ~37 ~4 ~21 nether_brick
fill ~31 ~5 ~15 ~37 ~5 ~21 nether_brick
setblock ~34 ~0 ~21 air
setblock ~34 ~1 ~21 air
setblock ~32 ~1 ~21 glass
setblock ~36 ~1 ~21 glass
fill ~31 ~2 ~22 ~37 ~2 ~22 orange_wool
setblock ~31 ~3 ~15 torch
setblock ~37 ~3 ~15 torch
setblock ~34 ~3 ~18 lantern
fill ~31 ~-1 ~31 ~37 ~-1 ~37 white_terracotta
fill ~31 ~0 ~31 ~37 ~3 ~31 white_terracotta
fill ~31 ~0 ~37 ~37 ~3 ~37 white_terracotta
fill ~31 ~0 ~31 ~31 ~3 ~37 white_terracotta
fill ~37 ~0 ~31 ~37 ~3 ~37 white_terracotta
fill ~31 ~4 ~31 ~37 ~4 ~37 stone_bricks
fill ~31 ~5 ~31 ~37 ~5 ~37 stone_bricks
setblock ~34 ~0 ~37 air
setblock ~34 ~1 ~37 air
setblock ~32 ~1 ~37 glass
setblock ~36 ~1 ~37 glass
fill ~31 ~2 ~38 ~37 ~2 ~38 red_wool
setblock ~31 ~3 ~31 torch
setblock ~37 ~3 ~31 torch
setblock ~34 ~3 ~34 lantern
# Dorpelingen
summon dorpsbaas:dorpeling ~-30 ~1 ~-35
summon dorpsbaas:dorpeling ~-30 ~1 ~-19
summon dorpsbaas:dorpeling ~-30 ~1 ~-3
summon dorpsbaas:dorpeling ~-30 ~1 ~13
summon dorpsbaas:dorpeling ~-30 ~1 ~29
summon dorpsbaas:dorpeling ~-14 ~1 ~-35
summon dorpsbaas:dorpeling ~-14 ~1 ~29
summon dorpsbaas:dorpeling ~2 ~1 ~-35
summon dorpsbaas:dorpeling ~2 ~1 ~29
summon dorpsbaas:dorpeling ~18 ~1 ~-35
summon dorpsbaas:dorpeling ~18 ~1 ~29
summon dorpsbaas:dorpeling ~34 ~1 ~-35
summon dorpsbaas:dorpeling ~34 ~1 ~-19
summon dorpsbaas:dorpeling ~34 ~1 ~-3
summon dorpsbaas:dorpeling ~34 ~1 ~13
summon dorpsbaas:dorpeling ~34 ~1 ~29
# klaar
